Generating LALR tables
Traceback (most recent call last):
  File "/Users/Grace/anaconda/envs/py35/lib/python3.5/asyncio/base_events.py", line 905, in create_server
    sock.bind(sa)
OSError: [Errno 48] Address already in use

During handling of the above exception, another exception occurred:

Traceback (most recent call last):
  File "go_web.py", line 8, in <module>
    main()
  File "go_web.py", line 5, in main
    webapp.run()
  File "/Users/Grace/harvard/spring2016/cs207/TimeSeries/web/web_application.py", line 105, in run
    web.run_app(self.app)
  File "/Users/Grace/anaconda/envs/py35/lib/python3.5/site-packages/aiohttp/web.py", line 309, in run_app
    ssl=ssl_context))
  File "/Users/Grace/anaconda/envs/py35/lib/python3.5/asyncio/base_events.py", line 337, in run_until_complete
    return future.result()
  File "/Users/Grace/anaconda/envs/py35/lib/python3.5/asyncio/futures.py", line 274, in result
    raise self._exception
  File "/Users/Grace/anaconda/envs/py35/lib/python3.5/asyncio/tasks.py", line 239, in _step
    result = coro.send(None)
  File "/Users/Grace/anaconda/envs/py35/lib/python3.5/asyncio/base_events.py", line 909, in create_server
    % (sa, err.strerror.lower()))
OSError: [Errno 48] error while attempting to bind on address ('0.0.0.0', 8080): address already in use
